[2024-02-20T18:43:57.114+0000] {taskinstance.py:1956} INFO - Dependencies all met for dep_context=non-requeueable deps ti=<TaskInstance: etl_reddit_pipeline.upload_s3 manual__2024-02-20T18:43:48.198671+00:00 [queued]>
[2024-02-20T18:43:57.130+0000] {taskinstance.py:1956} INFO - Dependencies all met for dep_context=requeueable deps ti=<TaskInstance: etl_reddit_pipeline.upload_s3 manual__2024-02-20T18:43:48.198671+00:00 [queued]>
[2024-02-20T18:43:57.131+0000] {taskinstance.py:2170} INFO - Starting attempt 1 of 1
[2024-02-20T18:43:57.152+0000] {taskinstance.py:2191} INFO - Executing <Task(PythonOperator): upload_s3> on 2024-02-20 18:43:48.198671+00:00
[2024-02-20T18:43:57.160+0000] {standard_task_runner.py:60} INFO - Started process 62 to run task
[2024-02-20T18:43:57.165+0000] {standard_task_runner.py:87} INFO - Running: ['airflow', 'tasks', 'run', 'etl_reddit_pipeline', 'upload_s3', 'manual__2024-02-20T18:43:48.198671+00:00', '--job-id', '5', '--raw', '--subdir', 'DAGS_FOLDER/reddit_dag.py', '--cfg-path', '/tmp/tmpin27fn5y']
[2024-02-20T18:43:57.168+0000] {standard_task_runner.py:88} INFO - Job 5: Subtask upload_s3
[2024-02-20T18:43:57.232+0000] {task_command.py:423} INFO - Running <TaskInstance: etl_reddit_pipeline.upload_s3 manual__2024-02-20T18:43:48.198671+00:00 [running]> on host 95cb6329b0b5
[2024-02-20T18:43:57.353+0000] {taskinstance.py:2480} INFO - Exporting env vars: AIRFLOW_CTX_DAG_OWNER='ACHRAF ZHAR' AIRFLOW_CTX_DAG_ID='etl_reddit_pipeline' AIRFLOW_CTX_TASK_ID='upload_s3' AIRFLOW_CTX_EXECUTION_DATE='2024-02-20T18:43:48.198671+00:00' AIRFLOW_CTX_TRY_NUMBER='1' AIRFLOW_CTX_DAG_RUN_ID='manual__2024-02-20T18:43:48.198671+00:00'
[2024-02-20T18:43:59.556+0000] {logging_mixin.py:188} INFO - Bucket already created
[2024-02-20T18:43:59.787+0000] {taskinstance.py:2698} ERROR - Task failed with exception
Traceback (most recent call last):
  File "/home/airflow/.local/lib/python3.8/site-packages/s3fs/core.py", line 706, in _lsdir
    async for c in self._iterdir(
  File "/home/airflow/.local/lib/python3.8/site-packages/s3fs/core.py", line 756, in _iterdir
    async for i in it:
  File "/home/airflow/.local/lib/python3.8/site-packages/aiobotocore/paginate.py", line 30, in __anext__
    response = await self._make_request(current_kwargs)
  File "/home/airflow/.local/lib/python3.8/site-packages/aiobotocore/client.py", line 408, in _make_api_call
    raise error_class(parsed_response, operation_name)
botocore.exceptions.ClientError: An error occurred (RequestTimeTooSkewed) when calling the ListObjectsV2 operation: The difference between the request time and the current time is too large.

The above exception was the direct cause of the following exception:

Traceback (most recent call last):
  File "/home/airflow/.local/lib/python3.8/site-packages/airflow/models/taskinstance.py", line 433, in _execute_task
    result = execute_callable(context=context, **execute_callable_kwargs)
  File "/home/airflow/.local/lib/python3.8/site-packages/airflow/operators/python.py", line 199, in execute
    return_value = self.execute_callable()
  File "/home/airflow/.local/lib/python3.8/site-packages/airflow/operators/python.py", line 216, in execute_callable
    return self.python_callable(*self.op_args, **self.op_kwargs)
  File "/opt/airflow/pipelines/aws_upload_pipeline.py", line 11, in upload_s3_pipeline
    upload_to_s3(s3, file_path, AWS_BUCKET_NAME, file_path.split('/')[-1])
  File "/opt/airflow/etls/aws_etl.py", line 27, in upload_to_s3
    s3.put(file_path, bucket+'/raw/'+file_name)
  File "/home/airflow/.local/lib/python3.8/site-packages/fsspec/asyn.py", line 118, in wrapper
    return sync(self.loop, func, *args, **kwargs)
  File "/home/airflow/.local/lib/python3.8/site-packages/fsspec/asyn.py", line 103, in sync
    raise return_result
  File "/home/airflow/.local/lib/python3.8/site-packages/fsspec/asyn.py", line 56, in _runner
    result[0] = await coro
  File "/home/airflow/.local/lib/python3.8/site-packages/fsspec/asyn.py", line 546, in _put
    trailing_sep(rpath) or await self._isdir(rpath)
  File "/home/airflow/.local/lib/python3.8/site-packages/s3fs/core.py", line 1411, in _isdir
    return bool(await self._lsdir(path))
  File "/home/airflow/.local/lib/python3.8/site-packages/s3fs/core.py", line 719, in _lsdir
    raise translate_boto_error(e)
PermissionError: The difference between the request time and the current time is too large.
[2024-02-20T18:43:59.816+0000] {taskinstance.py:1138} INFO - Marking task as FAILED. dag_id=etl_reddit_pipeline, task_id=upload_s3, execution_date=20240220T184348, start_date=20240220T184357, end_date=20240220T184359
[2024-02-20T18:43:59.851+0000] {standard_task_runner.py:107} ERROR - Failed to execute job 5 for task upload_s3 (The difference between the request time and the current time is too large.; 62)
[2024-02-20T18:43:59.884+0000] {local_task_job_runner.py:234} INFO - Task exited with return code 1
[2024-02-20T18:43:59.908+0000] {taskinstance.py:3280} INFO - 0 downstream tasks scheduled from follow-on schedule check
